Workbook

Sheet Executive Summary
A1: Marketing Campaign Performance — Executive Summary
A2: Week of 2024-12-09 | Channels: Email, Facebook Ads, Google Ads, TikTok Ads
A4: Key Findings
A5: ="Total spend across all channels: $"&TEXT(SUM('Efficiency Analysis'!B10:B13),"#,##0")&" | Total revenue: $"&TEXT(SUM('Efficiency Analysis'!C10:C13),"#,##0")&" | Total net profit: $"&TEXT(SUM('Efficiency Analysis'!I10:I13),"#,##0") -> Total spend across all channels: $104,682 | Total revenue: $631,976 | Total net profit: $255,518
A6: Email and Google Ads are the strongest performers: both clear the 4.0x ROAS target by a wide margin, sit well under the $50 CPA cap, and post the largest net profit contributions.
A7: Facebook Ads is profitable and on-benchmark for CTR, but its 3.22% conversion rate trails the 3.8% benchmark, and ROAS sits just under the 115% increase threshold — recommend holding budget flat.
A8: TikTok Ads is the clear underperformer: ROAS is less than 50% of target and CPA exceeds the $50 cap, driving a net loss for the week. It qualifies for a heavy budget cut.
A9: Recommended action: cut TikTok Ads spend by 45%, fund modest 15%-capped increases to Email and Google Ads, and hold the remainder in reserve pending next week's results.
A11: Reallocation Assumptions
A12: Decrease — Heavy (%) | B12: 0.45
A13: Decrease — Light (%) | B13: 0.25
A14: Increase Cap (%) | B14: 0.15
A15: Reallocation Limit ($) | B15: 10000
A16: Min Conversions for Eligibility | B16: 50
A19: Budget Reallocation
A20: Channel | B20: Current Spend | C20: Conversions | D20: Net Profit | E20: Eligible | F20: Classification | G20: Decrease $ | H20: Proposed Increase $ | I20: Capped Increase $ | J20: Final Change $ | K20: New Budget
A21: ='Efficiency Analysis'!A10 -> Email | B21: ='Efficiency Analysis'!B10 -> 1836.76 | C21: ='Efficiency Analysis'!E10 -> 2335 | D21: ='Efficiency Analysis'!I10 -> 133943.08 | E21: =IF(C21>=$B$16,"Yes","No") -> Yes | F21: =IF(E21="No","INSUFFICIENT_DATA -> MAINTAIN",IF(OR(AND('Efficiency Analysis'!F10<0.5*'Efficiency Analysis'!$B$6,D21<=0),AND('Efficiency Analysis'!G10>1.5*'Efficiency Analysis'!$B$7,D21<=0),AND('Efficiency Analysis'!F10<'Efficiency Analysis'!$B$6,'Efficiency Analysis'!G10>'Efficiency Analysis'!$B$7,D21<=0)),"DECREASE_HEAVY",IF(AND('Efficiency Analysis'!F10>=1.15*'Efficiency Analysis'!$B$6,'Efficiency Analysis'!G10<=0.8*'Efficiency Analysis'!$B$7,D21>0),"INCREASE",IF(OR('Efficiency Analysis'!F10<0.8*'Efficiency Analysis'!$B$6,'Efficiency Analysis'!G10>1.2*'Efficiency Analysis'!$B$7),"DECREASE_LIGHT","MAINTAIN")))) -> INCREASE | G21: =IF(F21="DECREASE_HEAVY",B21*$B$12,IF(F21="DECREASE_LIGHT",B21*$B$13,0)) -> 0 | H21: =IF(F21="INCREASE",$B$26*(D21/$B$27),0) -> 11260.071 | I21: =IF(F21="INCREASE",MIN(H21,B21*$B$14),0) -> 275.514 | J21: =IF(F21="INCREASE",I21*$B$29,-G21) -> 275.514 | K21: =B21+J21 -> 2112.274
A22: ='Efficiency Analysis'!A11 -> Facebook_Ads | B22: ='Efficiency Analysis'!B11 -> 36678.01 | C22: ='Efficiency Analysis'!E11 -> 1674 | D22: ='Efficiency Analysis'!I11 -> 57493.777 | E22: =IF(C22>=$B$16,"Yes","No") -> Yes | F22: =IF(E22="No","INSUFFICIENT_DATA -> MAINTAIN",IF(OR(AND('Efficiency Analysis'!F11<0.5*'Efficiency Analysis'!$B$6,D22<=0),AND('Efficiency Analysis'!G11>1.5*'Efficiency Analysis'!$B$7,D22<=0),AND('Efficiency Analysis'!F11<'Efficiency Analysis'!$B$6,'Efficiency Analysis'!G11>'Efficiency Analysis'!$B$7,D22<=0)),"DECREASE_HEAVY",IF(AND('Efficiency Analysis'!F11>=1.15*'Efficiency Analysis'!$B$6,'Efficiency Analysis'!G11<=0.8*'Efficiency Analysis'!$B$7,D22>0),"INCREASE",IF(OR('Efficiency Analysis'!F11<0.8*'Efficiency Analysis'!$B$6,'Efficiency Analysis'!G11>1.2*'Efficiency Analysis'!$B$7),"DECREASE_LIGHT","MAINTAIN")))) -> MAINTAIN | G22: =IF(F22="DECREASE_HEAVY",B22*$B$12,IF(F22="DECREASE_LIGHT",B22*$B$13,0)) -> 0 | H22: =IF(F22="INCREASE",$B$26*(D22/$B$27),0) -> 0 | I22: =IF(F22="INCREASE",MIN(H22,B22*$B$14),0) -> 0 | J22: =IF(F22="INCREASE",I22*$B$29,-G22) -> 0 | K22: =B22+J22 -> 36678.01
A23: ='Efficiency Analysis'!A12 -> Google_Ads | B23: ='Efficiency Analysis'!B12 -> 28184.51 | C23: ='Efficiency Analysis'!E12 -> 1651 | D23: ='Efficiency Analysis'!I12 -> 69377.155 | E23: =IF(C23>=$B$16,"Yes","No") -> Yes | F23: =IF(E23="No","INSUFFICIENT_DATA -> MAINTAIN",IF(OR(AND('Efficiency Analysis'!F12<0.5*'Efficiency Analysis'!$B$6,D23<=0),AND('Efficiency Analysis'!G12>1.5*'Efficiency Analysis'!$B$7,D23<=0),AND('Efficiency Analysis'!F12<'Efficiency Analysis'!$B$6,'Efficiency Analysis'!G12>'Efficiency Analysis'!$B$7,D23<=0)),"DECREASE_HEAVY",IF(AND('Efficiency Analysis'!F12>=1.15*'Efficiency Analysis'!$B$6,'Efficiency Analysis'!G12<=0.8*'Efficiency Analysis'!$B$7,D23>0),"INCREASE",IF(OR('Efficiency Analysis'!F12<0.8*'Efficiency Analysis'!$B$6,'Efficiency Analysis'!G12>1.2*'Efficiency Analysis'!$B$7),"DECREASE_LIGHT","MAINTAIN")))) -> INCREASE | G23: =IF(F23="DECREASE_HEAVY",B23*$B$12,IF(F23="DECREASE_LIGHT",B23*$B$13,0)) -> 0 | H23: =IF(F23="INCREASE",$B$26*(D23/$B$27),0) -> 5832.2658 | I23: =IF(F23="INCREASE",MIN(H23,B23*$B$14),0) -> 4227.6765 | J23: =IF(F23="INCREASE",I23*$B$29,-G23) -> 4227.6765 | K23: =B23+J23 -> 32412.186
A24: ='Efficiency Analysis'!A13 -> TikTok_Ads | B24: ='Efficiency Analysis'!B13 -> 37982.97 | C24: ='Efficiency Analysis'!E13 -> 663 | D24: ='Efficiency Analysis'!I13 -> -5295.9585 | E24: =IF(C24>=$B$16,"Yes","No") -> Yes | F24: =IF(E24="No","INSUFFICIENT_DATA -> MAINTAIN",IF(OR(AND('Efficiency Analysis'!F13<0.5*'Efficiency Analysis'!$B$6,D24<=0),AND('Efficiency Analysis'!G13>1.5*'Efficiency Analysis'!$B$7,D24<=0),AND('Efficiency Analysis'!F13<'Efficiency Analysis'!$B$6,'Efficiency Analysis'!G13>'Efficiency Analysis'!$B$7,D24<=0)),"DECREASE_HEAVY",IF(AND('Efficiency Analysis'!F13>=1.15*'Efficiency Analysis'!$B$6,'Efficiency Analysis'!G13<=0.8*'Efficiency Analysis'!$B$7,D24>0),"INCREASE",IF(OR('Efficiency Analysis'!F13<0.8*'Efficiency Analysis'!$B$6,'Efficiency Analysis'!G13>1.2*'Efficiency Analysis'!$B$7),"DECREASE_LIGHT","MAINTAIN")))) -> DECREASE_HEAVY | G24: =IF(F24="DECREASE_HEAVY",B24*$B$12,IF(F24="DECREASE_LIGHT",B24*$B$13,0)) -> 17092.337 | H24: =IF(F24="INCREASE",$B$26*(D24/$B$27),0) -> 0 | I24: =IF(F24="INCREASE",MIN(H24,B24*$B$14),0) -> 0 | J24: =IF(F24="INCREASE",I24*$B$29,-G24) -> -17092.337 | K24: =B24+J24 -> 20890.633
A26: Freed Budget ($) | B26: =SUM(G21:G24) -> 17092.337
A27: Sum Net Profit (INCREASE channels) | B27: =SUMIF(F21:F24,"INCREASE",D21:D24) -> 203320.24
A28: Sum Capped Increases ($) | B28: =SUM(I21:I24) -> 4503.1905
A29: Scale Factor (limit / sum capped, max 1) | B29: =IF($B$28=0,1,MIN(1,$B$15/$B$28)) -> 1
A30: Unallocated (Reserve) ($) | B30: =$B$26-SUM(J21:J24) -> 29681.482

Sheet Raw Data
A1: date | B1: campaign_name | C1: channel | D1: segment | E1: impressions | F1: clicks | G1: conversions | H1: spend | I1: revenue | J1: orders
A2: 2024-12-09 | B2: Holiday_Sale_Prospecting | C2: Facebook_Ads | D2: New_Customers | E2: 125279 | F2: 3169 | G2: 84 | H2: 2060.43 | I2: 7714.41 | J2: 84
A3: 2024-12-09 | B3: Holiday_Sale_Retargeting | C3: Facebook_Ads | D3: Retargeting | E3: 43118 | F3: 1724 | G3: 107 | H3: 1414.17 | I3: 11542.94 | J3: 107
A4: 2024-12-09 | B4: Product_Launch_Awareness | C4: Facebook_Ads | D4: New_Customers | E4: 96975 | F4: 2205 | G4: 38 | H4: 1544.07 | I4: 3371.63 | J4: 38
A5: 2024-12-09 | B5: Brand_Search | C5: Google_Ads | D5: New_Customers | E5: 15628 | F5: 775 | G5: 95 | H5: 813.82 | I5: 9750.01 | J5: 95
A6: 2024-12-09 | B6: Shopping_Campaigns | C6: Google_Ads | D6: New_Customers | E6: 77393 | F6: 1917 | G6: 57 | H6: 1629.03 | I6: 5306.69 | J6: 57
A7: 2024-12-09 | B7: Dynamic_Remarketing | C7: Google_Ads | D7: Retargeting | E7: 36298 | F7: 1366 | G7: 71 | H7: 1297.63 | I7: 7856.04 | J7: 71
A8: 2024-12-09 | B8: Influencer_Collab_Video | C8: TikTok_Ads | D8: New_Customers | E8: 244182 | F8: 4983 | G8: 47 | H8: 2890.61 | I8: 4057.74 | J8: 47
A9: 2024-12-09 | B9: UGC_Content_Campaign | C9: TikTok_Ads | D9: New_Customers | E9: 208784 | F9: 3839 | G9: 45 | H9: 2380.65 | I9: 4104.67 | J9: 45
A10: 2024-12-09 | B10: Weekly_Newsletter | C10: Email | D10: Loyalty | F10: 14001 | G10: 297 | H10: 279.3 | I10: 29050.54 | J10: 297
A11: 2024-12-09 | B11: Abandoned_Cart_Sequence | C11: Email | D11: Retargeting | F11: 2462 | G11: 84 | H11: 24.37 | I11: 9633.95 | J11: 84
A12: 2024-12-10 | B12: Holiday_Sale_Prospecting | C12: Facebook_Ads | D12: New_Customers | E12: 130163 | F12: 3293 | G12: 87 | H12: 2140.76 | I12: 8015.15 | J12: 87
A13: 2024-12-10 | B13: Holiday_Sale_Retargeting | C13: Facebook_Ads | D13: Retargeting | E13: 39463 | F13: 1578 | G13: 98 | H13: 1294.29 | I13: 10564.44 | J13: 98
A14: 2024-12-10 | B14: Product_Launch_Awareness | C14: Facebook_Ads | D14: New_Customers | E14: 98898 | F14: 2248 | G14: 39 | H14: 1574.69 | I14: 3438.51 | J14: 39
A15: 2024-12-10 | B15: Brand_Search | C15: Google_Ads | D15: New_Customers | E15: 17410 | F15: 863 | G15: 106 | H15: 906.65 | I15: 10862.09 | J15: 106
A16: 2024-12-10 | B16: Shopping_Campaigns | C16: Google_Ads | D16: New_Customers | E16: 93584 | F16: 2318 | G16: 69 | H16: 1969.82 | I16: 6416.83 | J16: 69
A17: 2024-12-10 | B17: Dynamic_Remarketing | C17: Google_Ads | D17: Retargeting | E17: 39271 | F17: 1478 | G17: 76 | H17: 1403.91 | I17: 8499.46 | J17: 76
A18: 2024-12-10 | B18: Influencer_Collab_Video | C18: TikTok_Ads | D18: New_Customers | E18: 290292 | F18: 5924 | G18: 56 | H18: 3436.45 | I18: 4823.97 | J18: 56
A19: 2024-12-10 | B19: UGC_Content_Campaign | C19: TikTok_Ads | D19: New_Customers | E19: 218783 | F19: 4023 | G19: 47 | H19: 2494.66 | I19: 4301.25 | J19: 47
A20: 2024-12-10 | B20: Weekly_Newsletter | C20: Email | D20: Loyalty | F20: 11265 | G20: 239 | H20: 224.73 | I20: 23374.21 | J20: 239
A21: 2024-12-10 | B21: Abandoned_Cart_Sequence | C21: Email | D21: Retargeting | F21: 2466 | G21: 84 | H21: 24.41 | I21: 9647.44 | J21: 84
A22: 2024-12-11 | B22: Holiday_Sale_Prospecting | C22: Facebook_Ads | D22: New_Customers | E22: 141306 | F22: 3575 | G22: 94 | H22: 2324.03 | I22: 8701.33 | J22: 94
A23: 2024-12-11 | B23: Holiday_Sale_Retargeting | C23: Facebook_Ads | D23: Retargeting | E23: 43932 | F23: 1756 | G23: 109 | H23: 1440.86 | I23: 11760.85 | J23: 109
A24: 2024-12-11 | B24: Product_Launch_Awareness | C24: Facebook_Ads | D24: New_Customers | E24: 86612 | F24: 1969 | G24: 34 | H24: 1379.06 | I24: 3011.33 | J24: 34
A25: 2024-12-11 | B25: Brand_Search | C25: Google_Ads | D25: New_Customers | E25: 14422 | F25: 715 | G25: 87 | H25: 751.06 | I25: 8998.08 | J25: 87
A26: 2024-12-11 | B26: Shopping_Campaigns | C26: Google_Ads | D26: New_Customers | E26: 80728 | F26: 1999 | G26: 59 | H26: 1699.22 | I26: 5535.35 | J26: 59
A27: 2024-12-11 | B27: Dynamic_Remarketing | C27: Google_Ads | D27: Retargeting | E27: 41764 | F27: 1571 | G27: 81 | H27: 1493.05 | I27: 9039.09 | J27: 81
A28: 2024-12-11 | B28: Influencer_Collab_Video | C28: TikTok_Ads | D28: New_Customers | E28: 288988 | F28: 5898 | G28: 56 | H28: 3421.01 | I28: 4802.29 | J28: 56
A29: 2024-12-11 | B29: UGC_Content_Campaign | C29: TikTok_Ads | D29: New_Customers | E29: 179785 | F29: 3306 | G29: 39 | H29: 2049.99 | I29: 3534.55 | J29: 39
A30: 2024-12-11 | B30: Weekly_Newsletter | C30: Email | D30: Loyalty | F30: 11140 | G30: 237 | H30: 222.24 | I30: 23115.38 | J30: 237
A31: 2024-12-11 | B31: Abandoned_Cart_Sequence | C31: Email | D31: Retargeting | F31: 2121 | G31: 72 | H31: 21 | I31: 8298.95 | J31: 72
A32: 2024-12-12 | B32: Holiday_Sale_Prospecting | C32: Facebook_Ads | D32: New_Customers | E32: 138154 | F32: 3495 | G32: 92 | H32: 2272.19 | I32: 8507.24 | J32: 92
A33: 2024-12-12 | B33: Holiday_Sale_Retargeting | C33: Facebook_Ads | D33: Retargeting | E33: 46835 | F33: 1873 | G33: 117 | H33: 1536.08 | I33: 12538.07 | J33: 117
A34: 2024-12-12 | B34: Product_Launch_Awareness | C34: Facebook_Ads | D34: New_Customers | E34: 95435 | F34: 2170 | G34: 37 | H34: 1519.55 | I34: 3318.1 | J34: 37
A35: 2024-12-12 | B35: Brand_Search | C35: Google_Ads | D35: New_Customers | E35: 15136 | F35: 750 | G35: 92 | H35: 788.21 | I35: 9443.2 | J35: 92
A36: 2024-12-12 | B36: Shopping_Campaigns | C36: Google_Ads | D36: New_Customers | E36: 79650 | F36: 1973 | G36: 58 | H36: 1676.54 | I36: 5461.45 | J36: 58
A37: 2024-12-12 | B37: Dynamic_Remarketing | C37: Google_Ads | D37: Retargeting | E37: 37349 | F37: 1405 | G37: 73 | H37: 1335.19 | I37: 8083.42 | J37: 73
A38: 2024-12-12 | B38: Influencer_Collab_Video | C38: TikTok_Ads | D38: New_Customers | E38: 242963 | F38: 4958 | G38: 47 | H38: 2876.18 | I38: 4037.48 | J38: 47
A39: 2024-12-12 | B39: UGC_Content_Campaign | C39: TikTok_Ads | D39: New_Customers | E39: 220333 | F39: 4051 | G39: 48 | H39: 2512.33 | I39: 4331.72 | J39: 48
A40: 2024-12-12 | B40: Weekly_Newsletter | C40: Email | D40: Loyalty | F40: 11610 | G40: 247 | H40: 231.6 | I40: 24089.32 | J40: 247
...

Sheet Funnel Analysis
A1: Funnel Analysis
A2: CTR = Clicks / Impressions. CVR = Conversions / Clicks. Benchmarks are editable inputs (blue).
A4: Channel | B4: Impressions | C4: Clicks | D4: Conversions | E4: CTR Actual % | F4: CTR Benchmark % | G4: CTR Diff (pp) | H4: CVR Actual % | I4: CVR Benchmark % | J4: CVR Diff (pp)
A5: Email | B5: =SUMIF('Raw Data'!$C$2:$C$71,$A5,'Raw Data'!$E$2:$E$71) -> 0 | C5: =SUMIF('Raw Data'!$C$2:$C$71,$A5,'Raw Data'!$F$2:$F$71) -> 100213 | D5: =SUMIF('Raw Data'!$C$2:$C$71,$A5,'Raw Data'!$G$2:$G$71) -> 2335 | E5: =IFERROR(C5/B5*100,"N/A") -> N/A | F5: 15 | G5: =IFERROR(E5-F5,"N/A") -> N/A | H5: =IFERROR(D5/C5*100,"N/A") -> 2.330037 | I5: 2.1 | J5: =IFERROR(H5-I5,"N/A") -> 0.23003702
A6: Facebook_Ads | B6: =SUMIF('Raw Data'!$C$2:$C$71,$A6,'Raw Data'!$E$2:$E$71) -> 1941612 | C6: =SUMIF('Raw Data'!$C$2:$C$71,$A6,'Raw Data'!$F$2:$F$71) -> 51940 | D6: =SUMIF('Raw Data'!$C$2:$C$71,$A6,'Raw Data'!$G$2:$G$71) -> 1674 | E6: =IFERROR(C6/B6*100,"N/A") -> 2.6750968 | F6: 2.5 | G6: =IFERROR(E6-F6,"N/A") -> 0.17509678 | H6: =IFERROR(D6/C6*100,"N/A") -> 3.2229496 | I6: 3.8 | J6: =IFERROR(H6-I6,"N/A") -> -0.57705044
A7: Google_Ads | B7: =SUMIF('Raw Data'!$C$2:$C$71,$A7,'Raw Data'!$E$2:$E$71) -> 978780 | C7: =SUMIF('Raw Data'!$C$2:$C$71,$A7,'Raw Data'!$F$2:$F$71) -> 30613 | D7: =SUMIF('Raw Data'!$C$2:$C$71,$A7,'Raw Data'!$G$2:$G$71) -> 1651 | E7: =IFERROR(C7/B7*100,"N/A") -> 3.1276691 | F7: 5 | G7: =IFERROR(E7-F7,"N/A") -> -1.8723309 | H7: =IFERROR(D7/C7*100,"N/A") -> 5.3931336 | I7: 4.5 | J7: =IFERROR(H7-I7,"N/A") -> 0.89313364
A8: TikTok_Ads | B8: =SUMIF('Raw Data'!$C$2:$C$71,$A8,'Raw Data'!$E$2:$E$71) -> 3260225 | C8: =SUMIF('Raw Data'!$C$2:$C$71,$A8,'Raw Data'!$F$2:$F$71) -> 63698 | D8: =SUMIF('Raw Data'!$C$2:$C$71,$A8,'Raw Data'!$G$2:$G$71) -> 663 | E8: =IFERROR(C8/B8*100,"N/A") -> 1.9537915 | F8: 2 | G8: =IFERROR(E8-F8,"N/A") -> -0.046208467 | H8: =IFERROR(D8/C8*100,"N/A") -> 1.040849 | I8: 0.9 | J8: =IFERROR(H8-I8,"N/A") -> 0.14084901

Sheet Efficiency Analysis
A1: Efficiency Analysis
A3: Assumptions
A4: Shipping Cost per Order ($) | B4: 8
A5: Product Cost (% of Revenue) | B5: 0.35
A6: Target ROAS (x) | B6: 4
A7: Max CPA ($) | B7: 50
A9: Channel | B9: Spend | C9: Revenue | D9: Orders | E9: Conversions | F9: ROAS | G9: CPA | H9: Total Costs | I9: Net Profit | J9: ROAS Status | K9: CPA Status | L9: Net Profit Status
A10: Email | B10: =SUMIF('Raw Data'!$C$2:$C$71,$A10,'Raw Data'!$H$2:$H$71) -> 1836.76 | C10: =SUMIF('Raw Data'!$C$2:$C$71,$A10,'Raw Data'!$I$2:$I$71) -> 237630.53 | D10: =SUMIF('Raw Data'!$C$2:$C$71,$A10,'Raw Data'!$J$2:$J$71) -> 2335 | E10: =SUMIF('Raw Data'!$C$2:$C$71,$A10,'Raw Data'!$G$2:$G$71) -> 2335 | F10: =IFERROR(C10/B10,"N/A") -> 129.37484 | G10: =IFERROR(B10/E10,"N/A") -> 0.78662099 | H10: =B10+D10*$B$4+C10*$B$5 -> 103687.45 | I10: =C10-H10 -> 133943.08 | J10: =IF(F10>=$B$6,"[OK] Above","[X] Below") -> [OK] Above | K10: =IF(G10<=$B$7,"[OK] Below","[X] Above") -> [OK] Below | L10: =IF(I10>0,"[OK] Positive","[X] Negative") -> [OK] Positive
A11: Facebook_Ads | B11: =SUMIF('Raw Data'!$C$2:$C$71,$A11,'Raw Data'!$H$2:$H$71) -> 36678.01 | C11: =SUMIF('Raw Data'!$C$2:$C$71,$A11,'Raw Data'!$I$2:$I$71) -> 165482.75 | D11: =SUMIF('Raw Data'!$C$2:$C$71,$A11,'Raw Data'!$J$2:$J$71) -> 1674 | E11: =SUMIF('Raw Data'!$C$2:$C$71,$A11,'Raw Data'!$G$2:$G$71) -> 1674 | F11: =IFERROR(C11/B11,"N/A") -> 4.5117701 | G11: =IFERROR(B11/E11,"N/A") -> 21.9104 | H11: =B11+D11*$B$4+C11*$B$5 -> 107988.97 | I11: =C11-H11 -> 57493.777 | J11: =IF(F11>=$B$6,"[OK] Above","[X] Below") -> [OK] Above | K11: =IF(G11<=$B$7,"[OK] Below","[X] Above") -> [OK] Below | L11: =IF(I11>0,"[OK] Positive","[X] Negative") -> [OK] Positive
A12: Google_Ads | B12: =SUMIF('Raw Data'!$C$2:$C$71,$A12,'Raw Data'!$H$2:$H$71) -> 28184.51 | C12: =SUMIF('Raw Data'!$C$2:$C$71,$A12,'Raw Data'!$I$2:$I$71) -> 170414.87 | D12: =SUMIF('Raw Data'!$C$2:$C$71,$A12,'Raw Data'!$J$2:$J$71) -> 1651 | E12: =SUMIF('Raw Data'!$C$2:$C$71,$A12,'Raw Data'!$G$2:$G$71) -> 1651 | F12: =IFERROR(C12/B12,"N/A") -> 6.0464017 | G12: =IFERROR(B12/E12,"N/A") -> 17.071175 | H12: =B12+D12*$B$4+C12*$B$5 -> 101037.71 | I12: =C12-H12 -> 69377.155 | J12: =IF(F12>=$B$6,"[OK] Above","[X] Below") -> [OK] Above | K12: =IF(G12<=$B$7,"[OK] Below","[X] Above") -> [OK] Below | L12: =IF(I12>0,"[OK] Positive","[X] Negative") -> [OK] Positive
A13: TikTok_Ads | B13: =SUMIF('Raw Data'!$C$2:$C$71,$A13,'Raw Data'!$H$2:$H$71) -> 37982.97 | C13: =SUMIF('Raw Data'!$C$2:$C$71,$A13,'Raw Data'!$I$2:$I$71) -> 58447.71 | D13: =SUMIF('Raw Data'!$C$2:$C$71,$A13,'Raw Data'!$J$2:$J$71) -> 663 | E13: =SUMIF('Raw Data'!$C$2:$C$71,$A13,'Raw Data'!$G$2:$G$71) -> 663 | F13: =IFERROR(C13/B13,"N/A") -> 1.5387873 | G13: =IFERROR(B13/E13,"N/A") -> 57.289548 | H13: =B13+D13*$B$4+C13*$B$5 -> 63743.668 | I13: =C13-H13 -> -5295.9585 | J13: =IF(F13>=$B$6,"[OK] Above","[X] Below") -> [X] Below | K13: =IF(G13<=$B$7,"[OK] Below","[X] Above") -> [X] Above | L13: =IF(I13>0,"[OK] Positive","[X] Negative") -> [X] Negative
